Workbook

Sheet Anleitung
A1: Buchhaltung Einzelfirma – Garage (Dornach SO)
A2: Arbeitsmappe für das Geschäftsjahr. Schweizer KMU-Kontenrahmen, MWST, AHV, Steuern.
A4: SO FUNKTIONIERT'S
A5: 1. Einstellungen | B5: Firma, Jahr, MWST-Methode (Saldo/Effektiv) und gelbe Annahmen prüfen (AK-Sätze, Steuersätze).
A6: 2. Kontenplan | B6: Eröffnungssalden per 1.1. aus der Schlussbilanz des Vorjahres in Spalte G eintragen. Kontrolle rechts muss 'ausgeglichen' zeigen.
A7: 3. Journal | B7: JEDEN Beleg erfassen: Datum, Beleg-Nr., Text, Soll-Konto, Haben-Konto, Betrag inkl. MWST, MWST-Code. Rest rechnet automatisch.
A8: 4. Nebenlisten | B8: Debitoren, Kreditoren, Fahrzeuge, Löhne, Lager, Anlagen führen – sie zeigen offene Posten, Margen und Abgleich zur Buchhaltung.
A9: 5. Auswerten | B9: Übersicht, Erfolgsrechnung, Bilanz, Margen, MWST, Steuern und Stundensatz aktualisieren sich automatisch.
A11: FARBEN
A12: Blaue Schrift | B12: Eingabefelder
A13: Gelb hinterlegt | B13: Wichtige Annahmen – prüfen und anpassen
A14: Grau hinterlegt | B14: Formeln – nicht überschreiben
A16: BUCHUNGSSATZ-SPICKZETTEL (Soll an Haben)
A17: Werkstattrechnung an Kunde | B17: 1100 an 3000 (Arbeit) / 3200 (Teile) · Code U81
A18: Barzahlung Kunde | B18: 1000 an 3000/3200/3210 · U81
A19: Kunde zahlt Rechnung | B19: 1020 an 1100 · –
A20: Einkauf Ersatzteile auf Rechnung | B20: 4000 an 2000 · V81
A21: Lieferantenrechnung bezahlen | B21: 2000 an 1020 · –
A22: Occasion ankaufen (von Privat) | B22: 4200 an 1020 · – (von Händler mit MWST: V81)
A23: Occasion verkaufen | B23: 1020 an 3400 · U81
A24: Fremdarbeit (Carrosserie/Lack) | B24: 4400 an 2000 · V81
A25: Miete Werkstatt | B25: 6000 an 1020 · – (ausser Vermieter optiert: V81)
A26: Strom, Telefon, Software, Werbung | B26: 6400 / 6500 / 6600 an 1020 · V81
A27: Versicherungsprämie | B27: 6300 an 1020 · – (keine MWST)
A28: Investition (Maschine, Werkzeug) | B28: 1500 / 1510 an 1020 · VI81 + Blatt Anlagen ergänzen
... A35: Debitorenverlust | B35: 3805 an 1100 · – (betrag inkl. MWST)
A37: AUTOMATISCH (nicht selbst buchen)
A38: Abschreibungen | B38: Aus Blatt Anlagen → Konto 6800 und Anlagekonten
A39: MWST Saldomethode | B39: Aus Blatt MWST → Konto 3809 (Ertragsminderung) und 2200
A40: MWST effektiv | B40: Aus MWST-Code: Netto auf Ertrag/Aufwand, MWST auf 2200 bzw. 1170/1171
A42: JAHRESABSCHLUSS – CHECKLISTE
A43: ☐ Kasse | B43: Bargeld zählen = Saldo Konto 1000 (Blatt Kontoauszug)
A44: ☐ Bank | B44: Saldo 1020 = Bankauszug 31.12.
A45: ☐ Debitoren / Kreditoren | B45: Listen vollständig, Abgleich 'stimmt'
A46: ☐ Inventur | B46: Blatt Lager ausfüllen, Bestandesänderung buchen; unverkaufte Fahrzeuge auf 1210
A47: ☐ Abgrenzungen | B47: Im Voraus bezahlte / noch nicht erhaltene Rechnungen (1300 / 2300)
A48: ☐ Anlagen | B48: Zugänge eingetragen, Abschreibungssätze ok
A49: ☐ MWST | B49: Umsatzabstimmung, letzte Abrechnung
A50: ☐ Privatanteile | B50: Auto, Telefon etc. im Blatt Steuern
A51: ☐ Bilanz ausgeglichen | B51: Blatt Bilanz Kontrolle = 0
...

Sheet Übersicht
A1: =Einstellungen!$B$5&" – Übersicht Geschäftsjahr "&Einstellungen!$B$7 -> Garage Muster, Dornach – Übersicht Geschäftsjahr 2026
A2: Alle Werte automatisch. Grün = gut, Rot = Handlungsbedarf.
A3: =Bilanz!F29 -> Bilanz ausgeglichen ✓
A5: Kennzahl | B5: Wert | C5: Erklärung | E5: Monat | F5: Ertrag netto | G5: Aufwand | H5: Gewinn | I5: Gewinn kumuliert
A6: Nettoerlös (Umsatz) | B6: =Erfolgsrechnung!C17 -> 18332.71 | C6: Alle Erträge nach Rabatten und MWST | E6: Jan | F6: =SUMIFS(Journal!$N$5:$N$1504,Journal!$U$5:$U$1504,"Ertrag",Journal!$O$5:$O$1504,1)-SUMIFS(Journal!$M$5:$M$1504,Journal!$T$5:$T$1504,"Ertrag",Journal!$O$5:$O$1504,1)-IF(MWST!$C$5,Einstellungen!$B$12*(SUMIFS(Journal!$F$5:$F$1504,Journal!$R$5:$R$1504,1,Journal!$O$5:$O$1504,1)-SUMIFS(Journal!$F$5:$F$1504,Journal!$S$5:$S$1504,1,Journal!$O$5:$O$1504,1))+Einstellungen!$B$13*(SUMIFS(Journal!$F$5:$F$1504,Journal!$R$5:$R$1504,2,Journal!$O$5:$O$1504,1)-SUMIFS(Journal!$F$5:$F$1504,Journal!$S$5:$S$1504,2,Journal!$O$5:$O$1504,1)),0) -> 2528.111 | G6: =SUMIFS(Journal!$M$5:$M$1504,Journal!$T$5:$T$1504,"Aufwand",Journal!$O$5:$O$1504,1)-SUMIFS(Journal!$N$5:$N$1504,Journal!$U$5:$U$1504,"Aufwand",Journal!$O$5:$O$1504,1)+Anlagen!$J$3/12 -> 13560.533 | H6: =F6-G6 -> -11032.422 | I6: =H6 -> -11032.422
A7: Bruttogewinn | B7: =Erfolgsrechnung!C29 -> 5035.51 | C7: Umsatz minus Material/Waren/Fremdarbeiten | E7: Feb | F7: =SUMIFS(Journal!$N$5:$N$1504,Journal!$U$5:$U$1504,"Ertrag",Journal!$O$5:$O$1504,2)-SUMIFS(Journal!$M$5:$M$1504,Journal!$T$5:$T$1504,"Ertrag",Journal!$O$5:$O$1504,2)-IF(MWST!$C$5,Einstellungen!$B$12*(SUMIFS(Journal!$F$5:$F$1504,Journal!$R$5:$R$1504,1,Journal!$O$5:$O$1504,2)-SUMIFS(Journal!$F$5:$F$1504,Journal!$S$5:$S$1504,1,Journal!$O$5:$O$1504,2))+Einstellungen!$B$13*(SUMIFS(Journal!$F$5:$F$1504,Journal!$R$5:$R$1504,2,Journal!$O$5:$O$1504,2)-SUMIFS(Journal!$F$5:$F$1504,Journal!$S$5:$S$1504,2,Journal!$O$5:$O$1504,2)),0) -> 0 | G7: =SUMIFS(Journal!$M$5:$M$1504,Journal!$T$5:$T$1504,"Aufwand",Journal!$O$5:$O$1504,2)-SUMIFS(Journal!$N$5:$N$1504,Journal!$U$5:$U$1504,"Aufwand",Journal!$O$5:$O$1504,2)+Anlagen!$J$3/12 -> 17669.933 | H7: =F7-G7 -> -17669.933 | I7: =I6+H7 -> -28702.356
A8: Bruttomarge | B8: =IF(B6=0,"",B7/B6) -> 0.27467352 | C8: Bruttogewinn in % vom Umsatz | E8: Mär | F8: =SUMIFS(Journal!$N$5:$N$1504,Journal!$U$5:$U$1504,"Ertrag",Journal!$O$5:$O$1504,3)-SUMIFS(Journal!$M$5:$M$1504,Journal!$T$5:$T$1504,"Ertrag",Journal!$O$5:$O$1504,3)-IF(MWST!$C$5,Einstellungen!$B$12*(SUMIFS(Journal!$F$5:$F$1504,Journal!$R$5:$R$1504,1,Journal!$O$5:$O$1504,3)-SUMIFS(Journal!$F$5:$F$1504,Journal!$S$5:$S$1504,1,Journal!$O$5:$O$1504,3))+Einstellungen!$B$13*(SUMIFS(Journal!$F$5:$F$1504,Journal!$R$5:$R$1504,2,Journal!$O$5:$O$1504,3)-SUMIFS(Journal!$F$5:$F$1504,Journal!$S$5:$S$1504,2,Journal!$O$5:$O$1504,3)),0) -> 15804.6 | G8: =SUMIFS(Journal!$M$5:$M$1504,Journal!$T$5:$T$1504,"Aufwand",Journal!$O$5:$O$1504,3)-SUMIFS(Journal!$N$5:$N$1504,Journal!$U$5:$U$1504,"Aufwand",Journal!$O$5:$O$1504,3)+Anlagen!$J$3/12 -> 3408.3333 | H8: =F8-G8 -> 12396.267 | I8: =I7+H8 -> -16306.089
A9: Personalaufwand | B9: =-Erfolgsrechnung!C36 -> 5980 | C9: Löhne + Sozialleistungen Mitarbeitende | E9: Apr | F9: =SUMIFS(Journal!$N$5:$N$1504,Journal!$U$5:$U$1504,"Ertrag",Journal!$O$5:$O$1504,4)-SUMIFS(Journal!$M$5:$M$1504,Journal!$T$5:$T$1504,"Ertrag",Journal!$O$5:$O$1504,4)-IF(MWST!$C$5,Einstellungen!$B$12*(SUMIFS(Journal!$F$5:$F$1504,Journal!$R$5:$R$1504,1,Journal!$O$5:$O$1504,4)-SUMIFS(Journal!$F$5:$F$1504,Journal!$S$5:$S$1504,1,Journal!$O$5:$O$1504,4))+Einstellungen!$B$13*(SUMIFS(Journal!$F$5:$F$1504,Journal!$R$5:$R$1504,2,Journal!$O$5:$O$1504,4)-SUMIFS(Journal!$F$5:$F$1504,Journal!$S$5:$S$1504,2,Journal!$O$5:$O$1504,4)),0) -> 0 | G9: =SUMIFS(Journal!$M$5:$M$1504,Journal!$T$5:$T$1504,"Aufwand",Journal!$O$5:$O$1504,4)-SUMIFS(Journal!$N$5:$N$1504,Journal!$U$5:$U$1504,"Aufwand",Journal!$O$5:$O$1504,4)+Anlagen!$J$3/12 -> 2783.3333 | H9: =F9-G9 -> -2783.3333 | I9: =I8+H9 -> -19089.422
A10: EBITDA | B10: =Erfolgsrechnung!C50 -> -7871.09 | C10: Ergebnis vor Abschreibungen | E10: Mai | F10: =SUMIFS(Journal!$N$5:$N$1504,Journal!$U$5:$U$1504,"Ertrag",Journal!$O$5:$O$1504,5)-SUMIFS(Journal!$M$5:$M$1504,Journal!$T$5:$T$1504,"Ertrag",Journal!$O$5:$O$1504,5)-IF(MWST!$C$5,Einstellungen!$B$12*(SUMIFS(Journal!$F$5:$F$1504,Journal!$R$5:$R$1504,1,Journal!$O$5:$O$1504,5)-SUMIFS(Journal!$F$5:$F$1504,Journal!$S$5:$S$1504,1,Journal!$O$5:$O$1504,5))+Einstellungen!$B$13*(SUMIFS(Journal!$F$5:$F$1504,Journal!$R$5:$R$1504,2,Journal!$O$5:$O$1504,5)-SUMIFS(Journal!$F$5:$F$1504,Journal!$S$5:$S$1504,2,Journal!$O$5:$O$1504,5)),0) -> 0 | G10: =SUMIFS(Journal!$M$5:$M$1504,Journal!$T$5:$T$1504,"Aufwand",Journal!$O$5:$O$1504,5)-SUMIFS(Journal!$N$5:$N$1504,Journal!$U$5:$U$1504,"Aufwand",Journal!$O$5:$O$1504,5)+Anlagen!$J$3/12 -> 2783.3333 | H10: =F10-G10 -> -2783.3333 | I10: =I9+H10 -> -21872.756
A11: Jahresgewinn (= dein Einkommen) | B11: =Erfolgsrechnung!$C$72 -> -41356.09 | C11: Vor AHV und Steuern des Inhabers | E11: Jun | F11: =SUMIFS(Journal!$N$5:$N$1504,Journal!$U$5:$U$1504,"Ertrag",Journal!$O$5:$O$1504,6)-SUMIFS(Journal!$M$5:$M$1504,Journal!$T$5:$T$1504,"Ertrag",Journal!$O$5:$O$1504,6)-IF(MWST!$C$5,Einstellungen!$B$12*(SUMIFS(Journal!$F$5:$F$1504,Journal!$R$5:$R$1504,1,Journal!$O$5:$O$1504,6)-SUMIFS(Journal!$F$5:$F$1504,Journal!$S$5:$S$1504,1,Journal!$O$5:$O$1504,6))+Einstellungen!$B$13*(SUMIFS(Journal!$F$5:$F$1504,Journal!$R$5:$R$1504,2,Journal!$O$5:$O$1504,6)-SUMIFS(Journal!$F$5:$F$1504,Journal!$S$5:$S$1504,2,Journal!$O$5:$O$1504,6)),0) -> 0 | G11: =SUMIFS(Journal!$M$5:$M$1504,Journal!$T$5:$T$1504,"Aufwand",Journal!$O$5:$O$1504,6)-SUMIFS(Journal!$N$5:$N$1504,Journal!$U$5:$U$1504,"Aufwand",Journal!$O$5:$O$1504,6)+Anlagen!$J$3/12 -> 2783.3333 | H11: =F11-G11 -> -2783.3333 | I11: =I10+H11 -> -24656.089
A12: Umsatzrendite | B12: =IF(B6=0,"",B11/B6) -> -2.2558634 | C12: Gewinn in % vom Umsatz | E12: Jul | F12: =SUMIFS(Journal!$N$5:$N$1504,Journal!$U$5:$U$1504,"Ertrag",Journal!$O$5:$O$1504,7)-SUMIFS(Journal!$M$5:$M$1504,Journal!$T$5:$T$1504,"Ertrag",Journal!$O$5:$O$1504,7)-IF(MWST!$C$5,Einstellungen!$B$12*(SUMIFS(Journal!$F$5:$F$1504,Journal!$R$5:$R$1504,1,Journal!$O$5:$O$1504,7)-SUMIFS(Journal!$F$5:$F$1504,Journal!$S$5:$S$1504,1,Journal!$O$5:$O$1504,7))+Einstellungen!$B$13*(SUMIFS(Journal!$F$5:$F$1504,Journal!$R$5:$R$1504,2,Journal!$O$5:$O$1504,7)-SUMIFS(Journal!$F$5:$F$1504,Journal!$S$5:$S$1504,2,Journal!$O$5:$O$1504,7)),0) -> 0 | G12: =SUMIFS(Journal!$M$5:$M$1504,Journal!$T$5:$T$1504,"Aufwand",Journal!$O$5:$O$1504,7)-SUMIFS(Journal!$N$5:$N$1504,Journal!$U$5:$U$1504,"Aufwand",Journal!$O$5:$O$1504,7)+Anlagen!$J$3/12 -> 2783.3333 | H12: =F12-G12 -> -2783.3333 | I12: =I11+H12 -> -27439.422
A13: Liquide Mittel (Kasse + Bank) | B13: =SUMIF(Kontenplan!$A$5:$A$90,1000,Kontenplan!$K$5:$K$90)+SUMIF(Kontenplan!$A$5:$A$90,1020,Kontenplan!$K$5:$K$90) -> 37844.7 | E13: Aug | F13: =SUMIFS(Journal!$N$5:$N$1504,Journal!$U$5:$U$1504,"Ertrag",Journal!$O$5:$O$1504,8)-SUMIFS(Journal!$M$5:$M$1504,Journal!$T$5:$T$1504,"Ertrag",Journal!$O$5:$O$1504,8)-IF(MWST!$C$5,Einstellungen!$B$12*(SUMIFS(Journal!$F$5:$F$1504,Journal!$R$5:$R$1504,1,Journal!$O$5:$O$1504,8)-SUMIFS(Journal!$F$5:$F$1504,Journal!$S$5:$S$1504,1,Journal!$O$5:$O$1504,8))+Einstellungen!$B$13*(SUMIFS(Journal!$F$5:$F$1504,Journal!$R$5:$R$1504,2,Journal!$O$5:$O$1504,8)-SUMIFS(Journal!$F$5:$F$1504,Journal!$S$5:$S$1504,2,Journal!$O$5:$O$1504,8)),0) -> 0 | G13: =SUMIFS(Journal!$M$5:$M$1504,Journal!$T$5:$T$1504,"Aufwand",Journal!$O$5:$O$1504,8)-SUMIFS(Journal!$N$5:$N$1504,Journal!$U$5:$U$1504,"Aufwand",Journal!$O$5:$O$1504,8)+Anlagen!$J$3/12 -> 2783.3333 | H13: =F13-G13 -> -2783.3333 | I13: =I12+H13 -> -30222.756
A14: Offene Debitoren | B14: =SUMIF(Kontenplan!$A$5:$A$90,1100,Kontenplan!$K$5:$K$90) -> 0 | C14: Überfällige siehe Blatt Debitoren | E14: Sep | F14: =SUMIFS(Journal!$N$5:$N$1504,Journal!$U$5:$U$1504,"Ertrag",Journal!$O$5:$O$1504,9)-SUMIFS(Journal!$M$5:$M$1504,Journal!$T$5:$T$1504,"Ertrag",Journal!$O$5:$O$1504,9)-IF(MWST!$C$5,Einstellungen!$B$12*(SUMIFS(Journal!$F$5:$F$1504,Journal!$R$5:$R$1504,1,Journal!$O$5:$O$1504,9)-SUMIFS(Journal!$F$5:$F$1504,Journal!$S$5:$S$1504,1,Journal!$O$5:$O$1504,9))+Einstellungen!$B$13*(SUMIFS(Journal!$F$5:$F$1504,Journal!$R$5:$R$1504,2,Journal!$O$5:$O$1504,9)-SUMIFS(Journal!$F$5:$F$1504,Journal!$S$5:$S$1504,2,Journal!$O$5:$O$1504,9)),0) -> 0 | G14: =SUMIFS(Journal!$M$5:$M$1504,Journal!$T$5:$T$1504,"Aufwand",Journal!$O$5:$O$1504,9)-SUMIFS(Journal!$N$5:$N$1504,Journal!$U$5:$U$1504,"Aufwand",Journal!$O$5:$O$1504,9)+Anlagen!$J$3/12 -> 2783.3333 | H14: =F14-G14 -> -2783.3333 | I14: =I13+H14 -> -33006.089
A15: Offene Kreditoren | B15: =SUMIF(Kontenplan!$A$5:$A$90,2000,Kontenplan!$K$5:$K$90) -> 1297.2 | E15: Okt | F15: =SUMIFS(Journal!$N$5:$N$1504,Journal!$U$5:$U$1504,"Ertrag",Journal!$O$5:$O$1504,10)-SUMIFS(Journal!$M$5:$M$1504,Journal!$T$5:$T$1504,"Ertrag",Journal!$O$5:$O$1504,10)-IF(MWST!$C$5,Einstellungen!$B$12*(SUMIFS(Journal!$F$5:$F$1504,Journal!$R$5:$R$1504,1,Journal!$O$5:$O$1504,10)-SUMIFS(Journal!$F$5:$F$1504,Journal!$S$5:$S$1504,1,Journal!$O$5:$O$1504,10))+Einstellungen!$B$13*(SUMIFS(Journal!$F$5:$F$1504,Journal!$R$5:$R$1504,2,Journal!$O$5:$O$1504,10)-SUMIFS(Journal!$F$5:$F$1504,Journal!$S$5:$S$1504,2,Journal!$O$5:$O$1504,10)),0) -> 0 | G15: =SUMIFS(Journal!$M$5:$M$1504,Journal!$T$5:$T$1504,"Aufwand",Journal!$O$5:$O$1504,10)-SUMIFS(Journal!$N$5:$N$1504,Journal!$U$5:$U$1504,"Aufwand",Journal!$O$5:$O$1504,10)+Anlagen!$J$3/12 -> 2783.3333 | H15: =F15-G15 -> -2783.3333 | I15: =I14+H15 -> -35789.422
A16: Liquiditätsgrad 2 | B16: =IF(Bilanz!G11=0,"",(B13+B14)/Bilanz!G11) -> 13.512152 | C16: Ziel > 100 % | E16: Nov | F16: =SUMIFS(Journal!$N$5:$N$1504,Journal!$U$5:$U$1504,"Ertrag",Journal!$O$5:$O$1504,11)-SUMIFS(Journal!$M$5:$M$1504,Journal!$T$5:$T$1504,"Ertrag",Journal!$O$5:$O$1504,11)-IF(MWST!$C$5,Einstellungen!$B$12*(SUMIFS(Journal!$F$5:$F$1504,Journal!$R$5:$R$1504,1,Journal!$O$5:$O$1504,11)-SUMIFS(Journal!$F$5:$F$1504,Journal!$S$5:$S$1504,1,Journal!$O$5:$O$1504,11))+Einstellungen!$B$13*(SUMIFS(Journal!$F$5:$F$1504,Journal!$R$5:$R$1504,2,Journal!$O$5:$O$1504,11)-SUMIFS(Journal!$F$5:$F$1504,Journal!$S$5:$S$1504,2,Journal!$O$5:$O$1504,11)),0) -> 0 | G16: =SUMIFS(Journal!$M$5:$M$1504,Journal!$T$5:$T$1504,"Aufwand",Journal!$O$5:$O$1504,11)-SUMIFS(Journal!$N$5:$N$1504,Journal!$U$5:$U$1504,"Aufwand",Journal!$O$5:$O$1504,11)+Anlagen!$J$3/12 -> 2783.3333 | H16: =F16-G16 -> -2783.3333 | I16: =I15+H16 -> -38572.756
A17: Eigenkapitalquote | B17: =IF(Bilanz!C27=0,"",Bilanz!G25/Bilanz!C27) -> 0.64166857 | C17: Eigenkapital / Bilanzsumme | E17: Dez | F17: =SUMIFS(Journal!$N$5:$N$1504,Journal!$U$5:$U$1504,"Ertrag",Journal!$O$5:$O$1504,12)-SUMIFS(Journal!$M$5:$M$1504,Journal!$T$5:$T$1504,"Ertrag",Journal!$O$5:$O$1504,12)-IF(MWST!$C$5,Einstellungen!$B$12*(SUMIFS(Journal!$F$5:$F$1504,Journal!$R$5:$R$1504,1,Journal!$O$5:$O$1504,12)-SUMIFS(Journal!$F$5:$F$1504,Journal!$S$5:$S$1504,1,Journal!$O$5:$O$1504,12))+Einstellungen!$B$13*(SUMIFS(Journal!$F$5:$F$1504,Journal!$R$5:$R$1504,2,Journal!$O$5:$O$1504,12)-SUMIFS(Journal!$F$5:$F$1504,Journal!$S$5:$S$1504,2,Journal!$O$5:$O$1504,12)),0) -> 0 | G17: =SUMIFS(Journal!$M$5:$M$1504,Journal!$T$5:$T$1504,"Aufwand",Journal!$O$5:$O$1504,12)-SUMIFS(Journal!$N$5:$N$1504,Journal!$U$5:$U$1504,"Aufwand",Journal!$O$5:$O$1504,12)+Anlagen!$J$3/12 -> 2783.3333 | H17: =F17-G17 -> -2783.3333 | I17: =I16+H17 -> -41356.089
A18: MWST noch offen | B18: =MWST!$B$29 -> 173.59 | C18: Zurücklegen – gehört der ESTV | E18: Total | F18: =SUM(F6:F17) -> 18332.711 | G18: =SUM(G6:G17) -> 59688.8 | H18: =SUM(H6:H17) -> -41356.089
A19: AHV + Steuern Inhaber (geschätzt) | B19: =Steuern!$C$21+Steuern!$C$42 -> 546 | C19: Siehe Blatt Steuern | E19: Abstimmung mit ER | H19: =IF(ABS(H18-Erfolgsrechnung!$C$72)<1,"✓","Differenz (Buchungen ausserhalb Jahr?)") -> ✓
A20: Rückstellung pro Monat empfohlen | B20: =Steuern!$C$53 -> 45.5 | C20: Monatlich auf separates Konto
A21: Frei verfügbar pro Monat (Schätzung) | B21: =Steuern!$C$51 -> -3491.8408 | C21: Nach AHV, Steuern und 3a
A22: Bisherige Privatbezüge | B22: =Steuern!$C$52 -> 4000
A23: Fahrzeuge an Lager | B23: =Fahrzeuge!$D$3 -> 0 | C23: Länger als 90 Tage: Preis prüfen
A24: Kostendeckender Stundensatz | B24: =Stundensatz!$C$29 -> 98.811664 | C24: exkl. MWST
A25: Journal-Zeilen mit Fehlern | B25: =COUNTIF(Journal!$V$5:$V$1504,"Konto prüfen!")+COUNTIF(Journal!$V$5:$V$1504,"Datum fehlt")+COUNTIF(Journal!$V$5:$V$1504,"anderes Jahr!")+COUNTIF(Journal!$V$5:$V$1504,"MWST-Code fehlt") -> 0 | C25: Muss 0 sein

Sheet Einstellungen
A1: Einstellungen & Sätze 2026
A2: Gelbe Felder anpassen. Blaue Schrift = Eingabe. Quellen in Spalte C.
A4: Parameter | B4: Wert | C4: Quelle / Hinweis | E4: MWST-Code | F4: Beschreibung | G4: Satz | H4: Art
A5: Firma | B5: Garage Muster, Dornach | C5: Eigene Angabe | E5: U81 | F5: Umsatz Normalsatz 8,1 % | G5: =Einstellungen!$B$10 -> 0.081 | H5: U
A6: Inhaber/in | B6: Vorname Name | C6: Eigene Angabe | E6: U26 | F6: Umsatz reduziert 2,6 % | G6: =Einstellungen!$B$11 -> 0.026 | H6: U
A7: Geschäftsjahr | B7: 2026 | E7: U0 | F7: Umsatz steuerfrei / Export 0 % | G7: 0 | H7: U
A8: MWST-pflichtig? (Ja/Nein) | B8: Ja | C8: Pflicht ab CHF 100'000 Umsatz/Jahr | E8: V81 | F8: Vorsteuer Material/DL 8,1 % | G8: =Einstellungen!$B$10 -> 0.081 | H8: V
A9: MWST-Methode (Saldo/Effektiv) | B9: Saldo | C9: Saldo: halbjährlich, pauschal. Effektiv: quartalsweise mit Vorsteuerabzug | E9: V26 | F9: Vorsteuer Material 2,6 % | G9: =Einstellungen!$B$11 -> 0.026 | H9: V
A10: MWST Normalsatz | B10: 0.081 | C10: ESTV, gültig seit 1.1.2024, 2026 unverändert | E10: VI81 | F10: Vorsteuer Investitionen 8,1 % | G10: =Einstellungen!$B$10 -> 0.081 | H10: V
A11: MWST reduzierter Satz | B11: 0.026 | C11: ESTV | E11: - | F11: ohne MWST (Lohn, Miete, Privat, Bank) | G11: 0 | H11: -
A12: Saldosteuersatz 1: Auto-Reparaturwerkstätte | B12: 0.03 | C12: ESTV-Verordnung Saldosteuersätze: Auto-Reparaturwerkstätte 3,0 % – bewilligten Satz aus ESTV-Verfügung eintragen
A13: Saldosteuersatz 2: Occasionen-/Neuwagenhandel | B13: 0.006 | C13: ESTV: Auto-Occasionen bis 3,5 t / Neuwagen Handel 0,6 %
E14: Anlagekategorie | F14: Satz degressiv | G14: Quelle
A15: AHV/IV/EO Satz Selbständige (max.) | B15: 0.1 | C15: BSV 2026: 8,1 % AHV + 1,4 % IV + 0,5 % EO = 10 % | E15: Maschinen & Apparate | F15: 0.3 | G15: ESTV Merkblatt A 1995 (Geschäftsbetriebe)
A16: Sinkende Skala: obere Grenze | B16: 60500 | C16: BSV 2026 | E16: Werkzeuge | F16: 0.45 | G16: ESTV Merkblatt A 1995 (Geschäftsbetriebe)
A17: Sinkende Skala: untere Grenze | B17: 10100 | C17: BSV 2026 | E17: Fahrzeuge | F17: 0.4 | G17: ESTV Merkblatt A 1995 (Geschäftsbetriebe)
A18: Sinkende Skala: tiefster Satz | B18: 0.05371 | C18: BSV 2026 | E18: Mobiliar & Einrichtungen | F18: 0.25 | G18: ESTV Merkblatt A 1995 (Geschäftsbetriebe)
A19: AHV-Mindestbeitrag | B19: 530 | C19: BSV 2026 | E19: EDV / Software | F19: 0.4 | G19: ESTV Merkblatt A 1995 (Geschäftsbetriebe)
A20: Verwaltungskosten Ausgleichskasse (% der Beiträge) | B20: 0.03 | C20: ANNAHME – Satz auf Rechnung der AK Solothurn prüfen | E20: Geschäftsliegenschaft | F20: 0.04 | G20: ESTV Merkblatt A 1995 (Geschäftsbetriebe)
A21: FAK-Beitrag Selbständige (% vom Einkommen) | B21: 0.012 | C21: ANNAHME – Satz bei der AK Solothurn prüfen
A22: Eigenkapitalzins-Abzug AHV | B22: 0.015 | C22: ANNAHME – Zinssatz gemäss AK (jährlich festgelegt)
A24: Steuerfuss Kanton Solothurn (nat. Personen) | B24: 1.04 | C24: Kantonsratsbeschluss Voranschlag 2026: 104 %
A25: Steuerfuss Gemeinde Dornach | B25: 0.92 | C25: Regierungsratsbeschluss 30.6.2026: 92 %
A26: Kirchensteuerfuss (0 wenn keine) | B26: 0 | C26: Dornach 2025: röm.-kath. 17 %, ref. 15 % – eintragen falls Mitglied
A27: Einfache Staatssteuer: Ø-Satz auf steuerb. Eink. | B27: 0.07 | C27: ANNAHME – mit Steuerrechner SO/ESTV ersetzen (abhängig von Einkommen, Zivilstand)
A28: Direkte Bundessteuer: Ø-Satz | B28: 0.02 | C28: ANNAHME – mit ESTV-Steuerrechner ersetzen
A29: Säule 3a Maximum ohne Pensionskasse | B29: 36288 | C29: 2026: 20 % des Erwerbseinkommens, max. CHF 36'288
A30: Privatanteil Geschäftsauto pro Monat | B30: 0.009 | C30: ESTV-Pauschale 0,9 % des Kaufpreises (exkl. MWST) pro Monat
A32: Löhne: AHV/IV/EO Arbeitnehmer | B32: 0.053 | C32: BSV 2026: 5,3 % AN + 5,3 % AG
A33: Löhne: AHV/IV/EO Arbeitgeber | B33: 0.053 | C33: BSV 2026
A34: Löhne: ALV je AN/AG | B34: 0.011 | C34: BSV 2026: 1,1 % bis CHF 148'200
... A40: Standard-Zahlungsfrist Kunden (Tage) | B40: 30 | C40: Eigene Angabe

Sheet Kontenplan
A1: Kontenplan (nach KMU-Kontenrahmen, angepasst für Garagen)
A2: Eröffnungssalden per 1.1. in Spalte G eintragen (blau). Neue Konten unten anfügen (bis Zeile 90) – Typ, Gruppe und Bereich ausfüllen.
A4: Konto | B4: Bezeichnung | C4: Typ | D4: Gruppe | E4: Bereich | F4: Saldo-satz-Gruppe | G4: Eröffnung 1.1. | H4: Soll | I4: Haben | J4: Automatisch (Abschluss) | K4: Saldo | M4: Kontrolle Eröffnung
A5: 1000 | B5: Kasse | C5: Aktiv | D5: UV | G5: 2000 | H5: =IF($A5="",0,SUMIFS(Journal!$M$5:$M$1504,Journal!$D$5:$D$1504,$A5)+IF($A5=1170,SUMIFS(Journal!$K$5:$K$1504,Journal!$J$5:$J$1504,"V",Journal!$G$5:$G$1504,"<>VI81"),0)+IF($A5=1171,SUMIFS(Journal!$K$5:$K$1504,Journal!$J$5:$J$1504,"V",Journal!$G$5:$G$1504,"VI81"),0)) -> 120 | I5: =IF($A5="",0,SUMIFS(Journal!$N$5:$N$1504,Journal!$E$5:$E$1504,$A5)+IF($A5=2200,SUMIFS(Journal!$K$5:$K$1504,Journal!$J$5:$J$1504,"U"),0)) -> 0 | J5: =IF($A5="",0,IF($A5=3809,-MWST!$H$13,IF($A5=2200,MWST!$H$13,IF($A5=6800,Anlagen!$J$3,-SUMIF(Anlagen!$B$6:$B$105,$A5,Anlagen!$J$6:$J$105))))) -> 0 | K5: =IF($A5="","",IF(OR($C5="Aktiv",$C5="Aufwand"),$G5+$H5-$I5+$J5,$G5+$I5-$H5+$J5)) -> 2120 | M5: Aktiven | N5: =SUMIFS(Kontenplan!$G$5:$G$90,Kontenplan!$C$5:$C$90,"Aktiv") -> 162000
A6: 1020 | B6: Bank | C6: Aktiv | D6: UV | G6: 45000 | H6: =IF($A6="",0,SUMIFS(Journal!$M$5:$M$1504,Journal!$D$5:$D$1504,$A6)+IF($A6=1170,SUMIFS(Journal!$K$5:$K$1504,Journal!$J$5:$J$1504,"V",Journal!$G$5:$G$1504,"<>VI81"),0)+IF($A6=1171,SUMIFS(Journal!$K$5:$K$1504,Journal!$J$5:$J$1504,"V",Journal!$G$5:$G$1504,"VI81"),0)) -> 18386.3 | I6: =IF($A6="",0,SUMIFS(Journal!$N$5:$N$1504,Journal!$E$5:$E$1504,$A6)+IF($A6=2200,SUMIFS(Journal!$K$5:$K$1504,Journal!$J$5:$J$1504,"U"),0)) -> 27661.6 | J6: =IF($A6="",0,IF($A6=3809,-MWST!$H$13,IF($A6=2200,MWST!$H$13,IF($A6=6800,Anlagen!$J$3,-SUMIF(Anlagen!$B$6:$B$105,$A6,Anlagen!$J$6:$J$105))))) -> 0 | K6: =IF($A6="","",IF(OR($C6="Aktiv",$C6="Aufwand"),$G6+$H6-$I6+$J6,$G6+$I6-$H6+$J6)) -> 35724.7 | M6: Passiven | N6: =SUMIFS(Kontenplan!$G$5:$G$90,Kontenplan!$C$5:$C$90,"Passiv") -> 162000
A7: 1100 | B7: Forderungen Kunden (Debitoren) | C7: Aktiv | D7: UV | G7: 0 | H7: =IF($A7="",0,SUMIFS(Journal!$M$5:$M$1504,Journal!$D$5:$D$1504,$A7)+IF($A7=1170,SUMIFS(Journal!$K$5:$K$1504,Journal!$J$5:$J$1504,"V",Journal!$G$5:$G$1504,"<>VI81"),0)+IF($A7=1171,SUMIFS(Journal!$K$5:$K$1504,Journal!$J$5:$J$1504,"V",Journal!$G$5:$G$1504,"VI81"),0)) -> 2486.3 | I7: =IF($A7="",0,SUMIFS(Journal!$N$5:$N$1504,Journal!$E$5:$E$1504,$A7)+IF($A7=2200,SUMIFS(Journal!$K$5:$K$1504,Journal!$J$5:$J$1504,"U"),0)) -> 2486.3 | J7: =IF($A7="",0,IF($A7=3809,-MWST!$H$13,IF($A7=2200,MWST!$H$13,IF($A7=6800,Anlagen!$J$3,-SUMIF(Anlagen!$B$6:$B$105,$A7,Anlagen!$J$6:$J$105))))) -> 0 | K7: =IF($A7="","",IF(OR($C7="Aktiv",$C7="Aufwand"),$G7+$H7-$I7+$J7,$G7+$I7-$H7+$J7)) -> 0 | M7: Differenz | N7: =N5-N6 -> 0
A8: 1170 | B8: Vorsteuer MWST Material/DL | C8: Aktiv | D8: UV | G8: 0 | H8: =IF($A8="",0,SUMIFS(Journal!$M$5:$M$1504,Journal!$D$5:$D$1504,$A8)+IF($A8=1170,SUMIFS(Journal!$K$5:$K$1504,Journal!$J$5:$J$1504,"V",Journal!$G$5:$G$1504,"<>VI81"),0)+IF($A8=1171,SUMIFS(Journal!$K$5:$K$1504,Journal!$J$5:$J$1504,"V",Journal!$G$5:$G$1504,"VI81"),0)) -> 0 | I8: =IF($A8="",0,SUMIFS(Journal!$N$5:$N$1504,Journal!$E$5:$E$1504,$A8)+IF($A8=2200,SUMIFS(Journal!$K$5:$K$1504,Journal!$J$5:$J$1504,"U"),0)) -> 0 | J8: =IF($A8="",0,IF($A8=3809,-MWST!$H$13,IF($A8=2200,MWST!$H$13,IF($A8=6800,Anlagen!$J$3,-SUMIF(Anlagen!$B$6:$B$105,$A8,Anlagen!$J$6:$J$105))))) -> 0 | K8: =IF($A8="","",IF(OR($C8="Aktiv",$C8="Aufwand"),$G8+$H8-$I8+$J8,$G8+$I8-$H8+$J8)) -> 0 | M8: Status | N8: =IF(ABS(N7)<0.01,"Eröffnungsbilanz ausgeglichen ✓","ACHTUNG: Eröffnung nicht ausgeglichen") -> Eröffnungsbilanz ausgeglichen ✓
A9: 1171 | B9: Vorsteuer MWST Investitionen | C9: Aktiv | D9: UV | G9: 0 | H9: =IF($A9="",0,SUMIFS(Journal!$M$5:$M$1504,Journal!$D$5:$D$1504,$A9)+IF($A9=1170,SUMIFS(Journal!$K$5:$K$1504,Journal!$J$5:$J$1504,"V",Journal!$G$5:$G$1504,"<>VI81"),0)+IF($A9=1171,SUMIFS(Journal!$K$5:$K$1504,Journal!$J$5:$J$1504,"V",Journal!$G$5:$G$1504,"VI81"),0)) -> 0 | I9: =IF($A9="",0,SUMIFS(Journal!$N$5:$N$1504,Journal!$E$5:$E$1504,$A9)+IF($A9=2200,SUMIFS(Journal!$K$5:$K$1504,Journal!$J$5:$J$1504,"U"),0)) -> 0 | J9: =IF($A9="",0,IF($A9=3809,-MWST!$H$13,IF($A9=2200,MWST!$H$13,IF($A9=6800,Anlagen!$J$3,-SUMIF(Anlagen!$B$6:$B$105,$A9,Anlagen!$J$6:$J$105))))) -> 0 | K9: =IF($A9="","",IF(OR($C9="Aktiv",$C9="Aufwand"),$G9+$H9-$I9+$J9,$G9+$I9-$H9+$J9)) -> 0
A10: 1200 | B10: Lager Ersatzteile, Pneus, Öl | C10: Aktiv | D10: UV | G10: 18000 | H10: =IF($A10="",0,SUMIFS(Journal!$M$5:$M$1504,Journal!$D$5:$D$1504,$A10)+IF($A10=1170,SUMIFS(Journal!$K$5:$K$1504,Journal!$J$5:$J$1504,"V",Journal!$G$5:$G$1504,"<>VI81"),0)+IF($A10=1171,SUMIFS(Journal!$K$5:$K$1504,Journal!$J$5:$J$1504,"V",Journal!$G$5:$G$1504,"VI81"),0)) -> 0 | I10: =IF($A10="",0,SUMIFS(Journal!$N$5:$N$1504,Journal!$E$5:$E$1504,$A10)+IF($A10=2200,SUMIFS(Journal!$K$5:$K$1504,Journal!$J$5:$J$1504,"U"),0)) -> 0 | J10: =IF($A10="",0,IF($A10=3809,-MWST!$H$13,IF($A10=2200,MWST!$H$13,IF($A10=6800,Anlagen!$J$3,-SUMIF(Anlagen!$B$6:$B$105,$A10,Anlagen!$J$6:$J$105))))) -> 0 | K10: =IF($A10="","",IF(OR($C10="Aktiv",$C10="Aufwand"),$G10+$H10-$I10+$J10,$G10+$I10-$H10+$J10)) -> 18000 | M10: Gruppen: UV Umlaufvermögen · AV Anlagevermögen · FKK kurzfr. FK · FKL langfr. FK · EK Eigenkapital
A11: 1210 | B11: Lager Fahrzeuge (Occasionen) | C11: Aktiv | D11: UV | G11: 0 | H11: =IF($A11="",0,SUMIFS(Journal!$M$5:$M$1504,Journal!$D$5:$D$1504,$A11)+IF($A11=1170,SUMIFS(Journal!$K$5:$K$1504,Journal!$J$5:$J$1504,"V",Journal!$G$5:$G$1504,"<>VI81"),0)+IF($A11=1171,SUMIFS(Journal!$K$5:$K$1504,Journal!$J$5:$J$1504,"V",Journal!$G$5:$G$1504,"VI81"),0)) -> 0 | I11: =IF($A11="",0,SUMIFS(Journal!$N$5:$N$1504,Journal!$E$5:$E$1504,$A11)+IF($A11=2200,SUMIFS(Journal!$K$5:$K$1504,Journal!$J$5:$J$1504,"U"),0)) -> 0 | J11: =IF($A11="",0,IF($A11=3809,-MWST!$H$13,IF($A11=2200,MWST!$H$13,IF($A11=6800,Anlagen!$J$3,-SUMIF(Anlagen!$B$6:$B$105,$A11,Anlagen!$J$6:$J$105))))) -> 0 | K11: =IF($A11="","",IF(OR($C11="Aktiv",$C11="Aufwand"),$G11+$H11-$I11+$J11,$G11+$I11-$H11+$J11)) -> 0 | M11: ERT Betriebsertrag · MAT Material/Waren · PERS Personal · BA Betriebsaufwand · ABS Abschreibungen
A12: 1300 | B12: Aktive Rechnungsabgrenzung | C12: Aktiv | D12: UV | G12: 0 | H12: =IF($A12="",0,SUMIFS(Journal!$M$5:$M$1504,Journal!$D$5:$D$1504,$A12)+IF($A12=1170,SUMIFS(Journal!$K$5:$K$1504,Journal!$J$5:$J$1504,"V",Journal!$G$5:$G$1504,"<>VI81"),0)+IF($A12=1171,SUMIFS(Journal!$K$5:$K$1504,Journal!$J$5:$J$1504,"V",Journal!$G$5:$G$1504,"VI81"),0)) -> 0 | I12: =IF($A12="",0,SUMIFS(Journal!$N$5:$N$1504,Journal!$E$5:$E$1504,$A12)+IF($A12=2200,SUMIFS(Journal!$K$5:$K$1504,Journal!$J$5:$J$1504,"U"),0)) -> 0 | J12: =IF($A12="",0,IF($A12=3809,-MWST!$H$13,IF($A12=2200,MWST!$H$13,IF($A12=6800,Anlagen!$J$3,-SUMIF(Anlagen!$B$6:$B$105,$A12,Anlagen!$J$6:$J$105))))) -> 0 | K12: =IF($A12="","",IF(OR($C12="Aktiv",$C12="Aufwand"),$G12+$H12-$I12+$J12,$G12+$I12-$H12+$J12)) -> 0 | M12: FINA/FINE Finanzaufwand/-ertrag · AO/AOE ausserordentlich
A13: 1500 | B13: Maschinen & Werkstatteinrichtung | C13: Aktiv | D13: AV | G13: 60000 | H13: =IF($A13="",0,SUMIFS(Journal!$M$5:$M$1504,Journal!$D$5:$D$1504,$A13)+IF($A13=1170,SUMIFS(Journal!$K$5:$K$1504,Journal!$J$5:$J$1504,"V",Journal!$G$5:$G$1504,"<>VI81"),0)+IF($A13=1171,SUMIFS(Journal!$K$5:$K$1504,Journal!$J$5:$J$1504,"V",Journal!$G$5:$G$1504,"VI81"),0)) -> 0 | I13: =IF($A13="",0,SUMIFS(Journal!$N$5:$N$1504,Journal!$E$5:$E$1504,$A13)+IF($A13=2200,SUMIFS(Journal!$K$5:$K$1504,Journal!$J$5:$J$1504,"U"),0)) -> 0 | J13: =IF($A13="",0,IF($A13=3809,-MWST!$H$13,IF($A13=2200,MWST!$H$13,IF($A13=6800,Anlagen!$J$3,-SUMIF(Anlagen!$B$6:$B$105,$A13,Anlagen!$J$6:$J$105))))) -> -18000 | K13: =IF($A13="","",IF(OR($C13="Aktiv",$C13="Aufwand"),$G13+$H13-$I13+$J13,$G13+$I13-$H13+$J13)) -> 42000 | M13: Saldosatz-Gruppe: 1 = Werkstatt-Satz, 2 = Fahrzeughandel-Satz (nur Ertragskonten)
A14: 1510 | B14: Werkzeuge | C14: Aktiv | D14: AV | G14: 12000 | H14: =IF($A14="",0,SUMIFS(Journal!$M$5:$M$1504,Journal!$D$5:$D$1504,$A14)+IF($A14=1170,SUMIFS(Journal!$K$5:$K$1504,Journal!$J$5:$J$1504,"V",Journal!$G$5:$G$1504,"<>VI81"),0)+IF($A14=1171,SUMIFS(Journal!$K$5:$K$1504,Journal!$J$5:$J$1504,"V",Journal!$G$5:$G$1504,"VI81"),0)) -> 0 | I14: =IF($A14="",0,SUMIFS(Journal!$N$5:$N$1504,Journal!$E$5:$E$1504,$A14)+IF($A14=2200,SUMIFS(Journal!$K$5:$K$1504,Journal!$J$5:$J$1504,"U"),0)) -> 0 | J14: =IF($A14="",0,IF($A14=3809,-MWST!$H$13,IF($A14=2200,MWST!$H$13,IF($A14=6800,Anlagen!$J$3,-SUMIF(Anlagen!$B$6:$B$105,$A14,Anlagen!$J$6:$J$105))))) -> -5400 | K14: =IF($A14="","",IF(OR($C14="Aktiv",$C14="Aufwand"),$G14+$H14-$I14+$J14,$G14+$I14-$H14+$J14)) -> 6600
A15: 1520 | B15: Büro, Mobiliar & EDV | C15: Aktiv | D15: AV | G15: 0 | H15: =IF($A15="",0,SUMIFS(Journal!$M$5:$M$1504,Journal!$D$5:$D$1504,$A15)+IF($A15=1170,SUMIFS(Journal!$K$5:$K$1504,Journal!$J$5:$J$1504,"V",Journal!$G$5:$G$1504,"<>VI81"),0)+IF($A15=1171,SUMIFS(Journal!$K$5:$K$1504,Journal!$J$5:$J$1504,"V",Journal!$G$5:$G$1504,"VI81"),0)) -> 0 | I15: =IF($A15="",0,SUMIFS(Journal!$N$5:$N$1504,Journal!$E$5:$E$1504,$A15)+IF($A15=2200,SUMIFS(Journal!$K$5:$K$1504,Journal!$J$5:$J$1504,"U"),0)) -> 0 | J15: =IF($A15="",0,IF($A15=3809,-MWST!$H$13,IF($A15=2200,MWST!$H$13,IF($A15=6800,Anlagen!$J$3,-SUMIF(Anlagen!$B$6:$B$105,$A15,Anlagen!$J$6:$J$105))))) -> 0 | K15: =IF($A15="","",IF(OR($C15="Aktiv",$C15="Aufwand"),$G15+$H15-$I15+$J15,$G15+$I15-$H15+$J15)) -> 0
A16: 1530 | B16: Fahrzeuge (Service-/Abschleppwagen) | C16: Aktiv | D16: AV | G16: 25000 | H16: =IF($A16="",0,SUMIFS(Journal!$M$5:$M$1504,Journal!$D$5:$D$1504,$A16)+IF($A16=1170,SUMIFS(Journal!$K$5:$K$1504,Journal!$J$5:$J$1504,"V",Journal!$G$5:$G$1504,"<>VI81"),0)+IF($A16=1171,SUMIFS(Journal!$K$5:$K$1504,Journal!$J$5:$J$1504,"V",Journal!$G$5:$G$1504,"VI81"),0)) -> 0 | I16: =IF($A16="",0,SUMIFS(Journal!$N$5:$N$1504,Journal!$E$5:$E$1504,$A16)+IF($A16=2200,SUMIFS(Journal!$K$5:$K$1504,Journal!$J$5:$J$1504,"U"),0)) -> 0 | J16: =IF($A16="",0,IF($A16=3809,-MWST!$H$13,IF($A16=2200,MWST!$H$13,IF($A16=6800,Anlagen!$J$3,-SUMIF(Anlagen!$B$6:$B$105,$A16,Anlagen!$J$6:$J$105))))) -> -10000 | K16: =IF($A16="","",IF(OR($C16="Aktiv",$C16="Aufwand"),$G16+$H16-$I16+$J16,$G16+$I16-$H16+$J16)) -> 15000
A17: 2000 | B17: Verbindlichkeiten Lieferanten (Kreditoren) | C17: Passiv | D17: FKK | G17: 0 | H17: =IF($A17="",0,SUMIFS(Journal!$M$5:$M$1504,Journal!$D$5:$D$1504,$A17)+IF($A17=1170,SUMIFS(Journal!$K$5:$K$1504,Journal!$J$5:$J$1504,"V",Journal!$G$5:$G$1504,"<>VI81"),0)+IF($A17=1171,SUMIFS(Journal!$K$5:$K$1504,Journal!$J$5:$J$1504,"V",Journal!$G$5:$G$1504,"VI81"),0)) -> 0 | I17: =IF($A17="",0,SUMIFS(Journal!$N$5:$N$1504,Journal!$E$5:$E$1504,$A17)+IF($A17=2200,SUMIFS(Journal!$K$5:$K$1504,Journal!$J$5:$J$1504,"U"),0)) -> 1297.2 | J17: =IF($A17="",0,IF($A17=3809,-MWST!$H$13,IF($A17=2200,MWST!$H$13,IF($A17=6800,Anlagen!$J$3,-SUMIF(Anlagen!$B$6:$B$105,$A17,Anlagen!$J$6:$J$105))))) -> 0 | K17: =IF($A17="","",IF(OR($C17="Aktiv",$C17="Aufwand"),$G17+$H17-$I17+$J17,$G17+$I17-$H17+$J17)) -> 1297.2
A18: 2200 | B18: Geschuldete MWST | C18: Passiv | D18: FKK | G18: 0 | H18: =IF($A18="",0,SUMIFS(Journal!$M$5:$M$1504,Journal!$D$5:$D$1504,$A18)+IF($A18=1170,SUMIFS(Journal!$K$5:$K$1504,Journal!$J$5:$J$1504,"V",Journal!$G$5:$G$1504,"<>VI81"),0)+IF($A18=1171,SUMIFS(Journal!$K$5:$K$1504,Journal!$J$5:$J$1504,"V",Journal!$G$5:$G$1504,"VI81"),0)) -> 0 | I18: =IF($A18="",0,SUMIFS(Journal!$N$5:$N$1504,Journal!$E$5:$E$1504,$A18)+IF($A18=2200,SUMIFS(Journal!$K$5:$K$1504,Journal!$J$5:$J$1504,"U"),0)) -> 0 | J18: =IF($A18="",0,IF($A18=3809,-MWST!$H$13,IF($A18=2200,MWST!$H$13,IF($A18=6800,Anlagen!$J$3,-SUMIF(Anlagen!$B$6:$B$105,$A18,Anlagen!$J$6:$J$105))))) -> 173.59 | K18: =IF($A18="","",IF(OR($C18="Aktiv",$C18="Aufwand"),$G18+$H18-$I18+$J18,$G18+$I18-$H18+$J18)) -> 173.59
A19: 2270 | B19: Sozialversicherungen (AHV, UVG, BVG) | C19: Passiv | D19: FKK | G19: 0 | H19: =IF($A19="",0,SUMIFS(Journal!$M$5:$M$1504,Journal!$D$5:$D$1504,$A19)+IF($A19=1170,SUMIFS(Journal!$K$5:$K$1504,Journal!$J$5:$J$1504,"V",Journal!$G$5:$G$1504,"<>VI81"),0)+IF($A19=1171,SUMIFS(Journal!$K$5:$K$1504,Journal!$J$5:$J$1504,"V",Journal!$G$5:$G$1504,"VI81"),0)) -> 0 | I19: =IF($A19="",0,SUMIFS(Journal!$N$5:$N$1504,Journal!$E$5:$E$1504,$A19)+IF($A19=2200,SUMIFS(Journal!$K$5:$K$1504,Journal!$J$5:$J$1504,"U"),0)) -> 1330 | J19: =IF($A19="",0,IF($A19=3809,-MWST!$H$13,IF($A19=2200,MWST!$H$13,IF($A19=6800,Anlagen!$J$3,-SUMIF(Anlagen!$B$6:$B$105,$A19,Anlagen!$J$6:$J$105))))) -> 0 | K19: =IF($A19="","",IF(OR($C19="Aktiv",$C19="Aufwand"),$G19+$H19-$I19+$J19,$G19+$I19-$H19+$J19)) -> 1330
A20: 2300 | B20: Passive Rechnungsabgrenzung | C20: Passiv | D20: FKK | G20: 0 | H20: =IF($A20="",0,SUMIFS(Journal!$M$5:$M$1504,Journal!$D$5:$D$1504,$A20)+IF($A20=1170,SUMIFS(Journal!$K$5:$K$1504,Journal!$J$5:$J$1504,"V",Journal!$G$5:$G$1504,"<>VI81"),0)+IF($A20=1171,SUMIFS(Journal!$K$5:$K$1504,Journal!$J$5:$J$1504,"V",Journal!$G$5:$G$1504,"VI81"),0)) -> 0 | I20: =IF($A20="",0,SUMIFS(Journal!$N$5:$N$1504,Journal!$E$5:$E$1504,$A20)+IF($A20=2200,SUMIFS(Journal!$K$5:$K$1504,Journal!$J$5:$J$1504,"U"),0)) -> 0 | J20: =IF($A20="",0,IF($A20=3809,-MWST!$H$13,IF($A20=2200,MWST!$H$13,IF($A20=6800,Anlagen!$J$3,-SUMIF(Anlagen!$B$6:$B$105,$A20,Anlagen!$J$6:$J$105))))) -> 0 | K20: =IF($A20="","",IF(OR($C20="Aktiv",$C20="Aufwand"),$G20+$H20-$I20+$J20,$G20+$I20-$H20+$J20)) -> 0
A21: 2400 | B21: Bankdarlehen | C21: Passiv | D21: FKL | G21: 40000 | H21: =IF($A21="",0,SUMIFS(Journal!$M$5:$M$1504,Journal!$D$5:$D$1504,$A21)+IF($A21=1170,SUMIFS(Journal!$K$5:$K$1504,Journal!$J$5:$J$1504,"V",Journal!$G$5:$G$1504,"<>VI81"),0)+IF($A21=1171,SUMIFS(Journal!$K$5:$K$1504,Journal!$J$5:$J$1504,"V",Journal!$G$5:$G$1504,"VI81"),0)) -> 0 | I21: =IF($A21="",0,SUMIFS(Journal!$N$5:$N$1504,Journal!$E$5:$E$1504,$A21)+IF($A21=2200,SUMIFS(Journal!$K$5:$K$1504,Journal!$J$5:$J$1504,"U"),0)) -> 0 | J21: =IF($A21="",0,IF($A21=3809,-MWST!$H$13,IF($A21=2200,MWST!$H$13,IF($A21=6800,Anlagen!$J$3,-SUMIF(Anlagen!$B$6:$B$105,$A21,Anlagen!$J$6:$J$105))))) -> 0 | K21: =IF($A21="","",IF(OR($C21="Aktiv",$C21="Aufwand"),$G21+$H21-$I21+$J21,$G21+$I21-$H21+$J21)) -> 40000
A22: 2450 | B22: Darlehen Dritte | C22: Passiv | D22: FKL | G22: 0 | H22: =IF($A22="",0,SUMIFS(Journal!$M$5:$M$1504,Journal!$D$5:$D$1504,$A22)+IF($A22=1170,SUMIFS(Journal!$K$5:$K$1504,Journal!$J$5:$J$1504,"V",Journal!$G$5:$G$1504,"<>VI81"),0)+IF($A22=1171,SUMIFS(Journal!$K$5:$K$1504,Journal!$J$5:$J$1504,"V",Journal!$G$5:$G$1504,"VI81"),0)) -> 0 | I22: =IF($A22="",0,SUMIFS(Journal!$N$5:$N$1504,Journal!$E$5:$E$1504,$A22)+IF($A22=2200,SUMIFS(Journal!$K$5:$K$1504,Journal!$J$5:$J$1504,"U"),0)) -> 0 | J22: =IF($A22="",0,IF($A22=3809,-MWST!$H$13,IF($A22=2200,MWST!$H$13,IF($A22=6800,Anlagen!$J$3,-SUMIF(Anlagen!$B$6:$B$105,$A22,Anlagen!$J$6:$J$105))))) -> 0 | K22: =IF($A22="","",IF(OR($C22="Aktiv",$C22="Aufwand"),$G22+$H22-$I22+$J22,$G22+$I22-$H22+$J22)) -> 0
A23: 2800 | B23: Eigenkapital | C23: Passiv | D23: EK | G23: 122000 | H23: =IF($A23="",0,SUMIFS(Journal!$M$5:$M$1504,Journal!$D$5:$D$1504,$A23)+IF($A23=1170,SUMIFS(Journal!$K$5:$K$1504,Journal!$J$5:$J$1504,"V",Journal!$G$5:$G$1504,"<>VI81"),0)+IF($A23=1171,SUMIFS(Journal!$K$5:$K$1504,Journal!$J$5:$J$1504,"V",Journal!$G$5:$G$1504,"VI81"),0)) -> 0 | I23: =IF($A23="",0,SUMIFS(Journal!$N$5:$N$1504,Journal!$E$5:$E$1504,$A23)+IF($A23=2200,SUMIFS(Journal!$K$5:$K$1504,Journal!$J$5:$J$1504,"U"),0)) -> 0 | J23: =IF($A23="",0,IF($A23=3809,-MWST!$H$13,IF($A23=2200,MWST!$H$13,IF($A23=6800,Anlagen!$J$3,-SUMIF(Anlagen!$B$6:$B$105,$A23,Anlagen!$J$6:$J$105))))) -> 0 | K23: =IF($A23="","",IF(OR($C23="Aktiv",$C23="Aufwand"),$G23+$H23-$I23+$J23,$G23+$I23-$H23+$J23)) -> 122000
A24: 2850 | B24: Privatkonto (Bezüge/Einlagen) | C24: Passiv | D24: EK | G24: 0 | H24: =IF($A24="",0,SUMIFS(Journal!$M$5:$M$1504,Journal!$D$5:$D$1504,$A24)+IF($A24=1170,SUMIFS(Journal!$K$5:$K$1504,Journal!$J$5:$J$1504,"V",Journal!$G$5:$G$1504,"<>VI81"),0)+IF($A24=1171,SUMIFS(Journal!$K$5:$K$1504,Journal!$J$5:$J$1504,"V",Journal!$G$5:$G$1504,"VI81"),0)) -> 4000 | I24: =IF($A24="",0,SUMIFS(Journal!$N$5:$N$1504,Journal!$E$5:$E$1504,$A24)+IF($A24=2200,SUMIFS(Journal!$K$5:$K$1504,Journal!$J$5:$J$1504,"U"),0)) -> 0 | J24: =IF($A24="",0,IF($A24=3809,-MWST!$H$13,IF($A24=2200,MWST!$H$13,IF($A24=6800,Anlagen!$J$3,-SUMIF(Anlagen!$B$6:$B$105,$A24,Anlagen!$J$6:$J$105))))) -> 0 | K24: =IF($A24="","",IF(OR($C24="Aktiv",$C24="Aufwand"),$G24+$H24-$I24+$J24,$G24+$I24-$H24+$J24)) -> -4000
A25: 3000 | B25: Werkstattarbeiten (Arbeitsstunden) | C25: Ertrag | D25: ERT | E25: Werkstatt | F25: 1 | G25: 0 | H25: =IF($A25="",0,SUMIFS(Journal!$M$5:$M$1504,Journal!$D$5:$D$1504,$A25)+IF($A25=1170,SUMIFS(Journal!$K$5:$K$1504,Journal!$J$5:$J$1504,"V",Journal!$G$5:$G$1504,"<>VI81"),0)+IF($A25=1171,SUMIFS(Journal!$K$5:$K$1504,Journal!$J$5:$J$1504,"V",Journal!$G$5:$G$1504,"VI81"),0)) -> 0 | I25: =IF($A25="",0,SUMIFS(Journal!$N$5:$N$1504,Journal!$E$5:$E$1504,$A25)+IF($A25=2200,SUMIFS(Journal!$K$5:$K$1504,Journal!$J$5:$J$1504,"U"),0)) -> 1621.5 | J25: =IF($A25="",0,IF($A25=3809,-MWST!$H$13,IF($A25=2200,MWST!$H$13,IF($A25=6800,Anlagen!$J$3,-SUMIF(Anlagen!$B$6:$B$105,$A25,Anlagen!$J$6:$J$105))))) -> 0 | K25: =IF($A25="","",IF(OR($C25="Aktiv",$C25="Aufwand"),$G25+$H25-$I25+$J25,$G25+$I25-$H25+$J25)) -> 1621.5
A26: 3010 | B26: Service, MFK-Vorbereitung, Klima | C26: Ertrag | D26: ERT | E26: Werkstatt | F26: 1 | G26: 0 | H26: =IF($A26="",0,SUMIFS(Journal!$M$5:$M$1504,Journal!$D$5:$D$1504,$A26)+IF($A26=1170,SUMIFS(Journal!$K$5:$K$1504,Journal!$J$5:$J$1504,"V",Journal!$G$5:$G$1504,"<>VI81"),0)+IF($A26=1171,SUMIFS(Journal!$K$5:$K$1504,Journal!$J$5:$J$1504,"V",Journal!$G$5:$G$1504,"VI81"),0)) -> 0 | I26: =IF($A26="",0,SUMIFS(Journal!$N$5:$N$1504,Journal!$E$5:$E$1504,$A26)+IF($A26=2200,SUMIFS(Journal!$K$5:$K$1504,Journal!$J$5:$J$1504,"U"),0)) -> 0 | J26: =IF($A26="",0,IF($A26=3809,-MWST!$H$13,IF($A26=2200,MWST!$H$13,IF($A26=6800,Anlagen!$J$3,-SUMIF(Anlagen!$B$6:$B$105,$A26,Anlagen!$J$6:$J$105))))) -> 0 | K26: =IF($A26="","",IF(OR($C26="Aktiv",$C26="Aufwand"),$G26+$H26-$I26+$J26,$G26+$I26-$H26+$J26)) -> 0
A27: 3200 | B27: Verkauf Ersatzteile & Zubehör | C27: Ertrag | D27: ERT | E27: Teile | F27: 1 | G27: 0 | H27: =IF($A27="",0,SUMIFS(Journal!$M$5:$M$1504,Journal!$D$5:$D$1504,$A27)+IF($A27=1170,SUMIFS(Journal!$K$5:$K$1504,Journal!$J$5:$J$1504,"V",Journal!$G$5:$G$1504,"<>VI81"),0)+IF($A27=1171,SUMIFS(Journal!$K$5:$K$1504,Journal!$J$5:$J$1504,"V",Journal!$G$5:$G$1504,"VI81"),0)) -> 0 | I27: =IF($A27="",0,SUMIFS(Journal!$N$5:$N$1504,Journal!$E$5:$E$1504,$A27)+IF($A27=2200,SUMIFS(Journal!$K$5:$K$1504,Journal!$J$5:$J$1504,"U"),0)) -> 864.8 | J27: =IF($A27="",0,IF($A27=3809,-MWST!$H$13,IF($A27=2200,MWST!$H$13,IF($A27=6800,Anlagen!$J$3,-SUMIF(Anlagen!$B$6:$B$105,$A27,Anlagen!$J$6:$J$105))))) -> 0 | K27: =IF($A27="","",IF(OR($C27="Aktiv",$C27="Aufwand"),$G27+$H27-$I27+$J27,$G27+$I27-$H27+$J27)) -> 864.8
A28: 3210 | B28: Verkauf Pneus & Pneuhotel | C28: Ertrag | D28: ERT | E28: Teile | F28: 1 | G28: 0 | H28: =IF($A28="",0,SUMIFS(Journal!$M$5:$M$1504,Journal!$D$5:$D$1504,$A28)+IF($A28=1170,SUMIFS(Journal!$K$5:$K$1504,Journal!$J$5:$J$1504,"V",Journal!$G$5:$G$1504,"<>VI81"),0)+IF($A28=1171,SUMIFS(Journal!$K$5:$K$1504,Journal!$J$5:$J$1504,"V",Journal!$G$5:$G$1504,"VI81"),0)) -> 0 | I28: =IF($A28="",0,SUMIFS(Journal!$N$5:$N$1504,Journal!$E$5:$E$1504,$A28)+IF($A28=2200,SUMIFS(Journal!$K$5:$K$1504,Journal!$J$5:$J$1504,"U"),0)) -> 120 | J28: =IF($A28="",0,IF($A28=3809,-MWST!$H$13,IF($A28=2200,MWST!$H$13,IF($A28=6800,Anlagen!$J$3,-SUMIF(Anlagen!$B$6:$B$105,$A28,Anlagen!$J$6:$J$105))))) -> 0 | K28: =IF($A28="","",IF(OR($C28="Aktiv",$C28="Aufwand"),$G28+$H28-$I28+$J28,$G28+$I28-$H28+$J28)) -> 120
A29: 3400 | B29: Verkauf Occasionen | C29: Ertrag | D29: ERT | E29: Fahrzeuge | F29: 2 | G29: 0 | H29: =IF($A29="",0,SUMIFS(Journal!$M$5:$M$1504,Journal!$D$5:$D$1504,$A29)+IF($A29=1170,SUMIFS(Journal!$K$5:$K$1504,Journal!$J$5:$J$1504,"V",Journal!$G$5:$G$1504,"<>VI81"),0)+IF($A29=1171,SUMIFS(Journal!$K$5:$K$1504,Journal!$J$5:$J$1504,"V",Journal!$G$5:$G$1504,"VI81"),0)) -> 0 | I29: =IF($A29="",0,SUMIFS(Journal!$N$5:$N$1504,Journal!$E$5:$E$1504,$A29)+IF($A29=2200,SUMIFS(Journal!$K$5:$K$1504,Journal!$J$5:$J$1504,"U"),0)) -> 15900 | J29: =IF($A29="",0,IF($A29=3809,-MWST!$H$13,IF($A29=2200,MWST!$H$13,IF($A29=6800,Anlagen!$J$3,-SUMIF(Anlagen!$B$6:$B$105,$A29,Anlagen!$J$6:$J$105))))) -> 0 | K29: =IF($A29="","",IF(OR($C29="Aktiv",$C29="Aufwand"),$G29+$H29-$I29+$J29,$G29+$I29-$H29+$J29)) -> 15900
A30: 3410 | B30: Verkauf Neuwagen | C30: Ertrag | D30: ERT | E30: Fahrzeuge | F30: 2 | G30: 0 | H30: =IF($A30="",0,SUMIFS(Journal!$M$5:$M$1504,Journal!$D$5:$D$1504,$A30)+IF($A30=1170,SUMIFS(Journal!$K$5:$K$1504,Journal!$J$5:$J$1504,"V",Journal!$G$5:$G$1504,"<>VI81"),0)+IF($A30=1171,SUMIFS(Journal!$K$5:$K$1504,Journal!$J$5:$J$1504,"V",Journal!$G$5:$G$1504,"VI81"),0)) -> 0 | I30: =IF($A30="",0,SUMIFS(Journal!$N$5:$N$1504,Journal!$E$5:$E$1504,$A30)+IF($A30=2200,SUMIFS(Journal!$K$5:$K$1504,Journal!$J$5:$J$1504,"U"),0)) -> 0 | J30: =IF($A30="",0,IF($A30=3809,-MWST!$H$13,IF($A30=2200,MWST!$H$13,IF($A30=6800,Anlagen!$J$3,-SUMIF(Anlagen!$B$6:$B$105,$A30,Anlagen!$J$6:$J$105))))) -> 0 | K30: =IF($A30="","",IF(OR($C30="Aktiv",$C30="Aufwand"),$G30+$H30-$I30+$J30,$G30+$I30-$H30+$J30)) -> 0
A31: 3600 | B31: Übriger Ertrag (Abschleppdienst, Vermietung) | C31: Ertrag | D31: ERT | E31: Allgemein | F31: 1 | G31: 0 | H31: =IF($A31="",0,SUMIFS(Journal!$M$5:$M$1504,Journal!$D$5:$D$1504,$A31)+IF($A31=1170,SUMIFS(Journal!$K$5:$K$1504,Journal!$J$5:$J$1504,"V",Journal!$G$5:$G$1504,"<>VI81"),0)+IF($A31=1171,SUMIFS(Journal!$K$5:$K$1504,Journal!$J$5:$J$1504,"V",Journal!$G$5:$G$1504,"VI81"),0)) -> 0 | I31: =IF($A31="",0,SUMIFS(Journal!$N$5:$N$1504,Journal!$E$5:$E$1504,$A31)+IF($A31=2200,SUMIFS(Journal!$K$5:$K$1504,Journal!$J$5:$J$1504,"U"),0)) -> 0 | J31: =IF($A31="",0,IF($A31=3809,-MWST!$H$13,IF($A31=2200,MWST!$H$13,IF($A31=6800,Anlagen!$J$3,-SUMIF(Anlagen!$B$6:$B$105,$A31,Anlagen!$J$6:$J$105))))) -> 0 | K31: =IF($A31="","",IF(OR($C31="Aktiv",$C31="Aufwand"),$G31+$H31-$I31+$J31,$G31+$I31-$H31+$J31)) -> 0
A32: 3800 | B32: Rabatte & Skonti an Kunden | C32: Ertrag | D32: ERT | E32: Allgemein | F32: 1 | G32: 0 | H32: =IF($A32="",0,SUMIFS(Journal!$M$5:$M$1504,Journal!$D$5:$D$1504,$A32)+IF($A32=1170,SUMIFS(Journal!$K$5:$K$1504,Journal!$J$5:$J$1504,"V",Journal!$G$5:$G$1504,"<>VI81"),0)+IF($A32=1171,SUMIFS(Journal!$K$5:$K$1504,Journal!$J$5:$J$1504,"V",Journal!$G$5:$G$1504,"VI81"),0)) -> 0 | I32: =IF($A32="",0,SUMIFS(Journal!$N$5:$N$1504,Journal!$E$5:$E$1504,$A32)+IF($A32=2200,SUMIFS(Journal!$K$5:$K$1504,Journal!$J$5:$J$1504,"U"),0)) -> 0 | J32: =IF($A32="",0,IF($A32=3809,-MWST!$H$13,IF($A32=2200,MWST!$H$13,IF($A32=6800,Anlagen!$J$3,-SUMIF(Anlagen!$B$6:$B$105,$A32,Anlagen!$J$6:$J$105))))) -> 0 | K32: =IF($A32="","",IF(OR($C32="Aktiv",$C32="Aufwand"),$G32+$H32-$I32+$J32,$G32+$I32-$H32+$J32)) -> 0
A33: 3805 | B33: Debitorenverluste | C33: Ertrag | D33: ERT | E33: Allgemein | F33: 1 | G33: 0 | H33: =IF($A33="",0,SUMIFS(Journal!$M$5:$M$1504,Journal!$D$5:$D$1504,$A33)+IF($A33=1170,SUMIFS(Journal!$K$5:$K$1504,Journal!$J$5:$J$1504,"V",Journal!$G$5:$G$1504,"<>VI81"),0)+IF($A33=1171,SUMIFS(Journal!$K$5:$K$1504,Journal!$J$5:$J$1504,"V",Journal!$G$5:$G$1504,"VI81"),0)) -> 0 | I33: =IF($A33="",0,SUMIFS(Journal!$N$5:$N$1504,Journal!$E$5:$E$1504,$A33)+IF($A33=2200,SUMIFS(Journal!$K$5:$K$1504,Journal!$J$5:$J$1504,"U"),0)) -> 0 | J33: =IF($A33="",0,IF($A33=3809,-MWST!$H$13,IF($A33=2200,MWST!$H$13,IF($A33=6800,Anlagen!$J$3,-SUMIF(Anlagen!$B$6:$B$105,$A33,Anlagen!$J$6:$J$105))))) -> 0 | K33: =IF($A33="","",IF(OR($C33="Aktiv",$C33="Aufwand"),$G33+$H33-$I33+$J33,$G33+$I33-$H33+$J33)) -> 0
A34: 3809 | B34: MWST Saldosteuersatz (automatisch) | C34: Ertrag | D34: ERT | E34: Allgemein | G34: 0 | H34: =IF($A34="",0,SUMIFS(Journal!$M$5:$M$1504,Journal!$D$5:$D$1504,$A34)+IF($A34=1170,SUMIFS(Journal!$K$5:$K$1504,Journal!$J$5:$J$1504,"V",Journal!$G$5:$G$1504,"<>VI81"),0)+IF($A34=1171,SUMIFS(Journal!$K$5:$K$1504,Journal!$J$5:$J$1504,"V",Journal!$G$5:$G$1504,"VI81"),0)) -> 0 | I34: =IF($A34="",0,SUMIFS(Journal!$N$5:$N$1504,Journal!$E$5:$E$1504,$A34)+IF($A34=2200,SUMIFS(Journal!$K$5:$K$1504,Journal!$J$5:$J$1504,"U"),0)) -> 0 | J34: =IF($A34="",0,IF($A34=3809,-MWST!$H$13,IF($A34=2200,MWST!$H$13,IF($A34=6800,Anlagen!$J$3,-SUMIF(Anlagen!$B$6:$B$105,$A34,Anlagen!$J$6:$J$105))))) -> -173.59 | K34: =IF($A34="","",IF(OR($C34="Aktiv",$C34="Aufwand"),$G34+$H34-$I34+$J34,$G34+$I34-$H34+$J34)) -> -173.59
A35: 4000 | B35: Einkauf Ersatzteile & Zubehör | C35: Aufwand | D35: MAT | E35: Teile | G35: 0 | H35: =IF($A35="",0,SUMIFS(Journal!$M$5:$M$1504,Journal!$D$5:$D$1504,$A35)+IF($A35=1170,SUMIFS(Journal!$K$5:$K$1504,Journal!$J$5:$J$1504,"V",Journal!$G$5:$G$1504,"<>VI81"),0)+IF($A35=1171,SUMIFS(Journal!$K$5:$K$1504,Journal!$J$5:$J$1504,"V",Journal!$G$5:$G$1504,"VI81"),0)) -> 1297.2 | I35: =IF($A35="",0,SUMIFS(Journal!$N$5:$N$1504,Journal!$E$5:$E$1504,$A35)+IF($A35=2200,SUMIFS(Journal!$K$5:$K$1504,Journal!$J$5:$J$1504,"U"),0)) -> 0 | J35: =IF($A35="",0,IF($A35=3809,-MWST!$H$13,IF($A35=2200,MWST!$H$13,IF($A35=6800,Anlagen!$J$3,-SUMIF(Anlagen!$B$6:$B$105,$A35,Anlagen!$J$6:$J$105))))) -> 0 | K35: =IF($A35="","",IF(OR($C35="Aktiv",$C35="Aufwand"),$G35+$H35-$I35+$J35,$G35+$I35-$H35+$J35)) -> 1297.2
A36: 4010 | B36: Einkauf Pneus | C36: Aufwand | D36: MAT | E36: Teile | G36: 0 | H36: =IF($A36="",0,SUMIFS(Journal!$M$5:$M$1504,Journal!$D$5:$D$1504,$A36)+IF($A36=1170,SUMIFS(Journal!$K$5:$K$1504,Journal!$J$5:$J$1504,"V",Journal!$G$5:$G$1504,"<>VI81"),0)+IF($A36=1171,SUMIFS(Journal!$K$5:$K$1504,Journal!$J$5:$J$1504,"V",Journal!$G$5:$G$1504,"VI81"),0)) -> 0 | I36: =IF($A36="",0,SUMIFS(Journal!$N$5:$N$1504,Journal!$E$5:$E$1504,$A36)+IF($A36=2200,SUMIFS(Journal!$K$5:$K$1504,Journal!$J$5:$J$1504,"U"),0)) -> 0 | J36: =IF($A36="",0,IF($A36=3809,-MWST!$H$13,IF($A36=2200,MWST!$H$13,IF($A36=6800,Anlagen!$J$3,-SUMIF(Anlagen!$B$6:$B$105,$A36,Anlagen!$J$6:$J$105))))) -> 0 | K36: =IF($A36="","",IF(OR($C36="Aktiv",$C36="Aufwand"),$G36+$H36-$I36+$J36,$G36+$I36-$H36+$J36)) -> 0
A37: 4200 | B37: Einkauf Fahrzeuge | C37: Aufwand | D37: MAT | E37: Fahrzeuge | G37: 0 | H37: =IF($A37="",0,SUMIFS(Journal!$M$5:$M$1504,Journal!$D$5:$D$1504,$A37)+IF($A37=1170,SUMIFS(Journal!$K$5:$K$1504,Journal!$J$5:$J$1504,"V",Journal!$G$5:$G$1504,"<>VI81"),0)+IF($A37=1171,SUMIFS(Journal!$K$5:$K$1504,Journal!$J$5:$J$1504,"V",Journal!$G$5:$G$1504,"VI81"),0)) -> 12000 | I37: =IF($A37="",0,SUMIFS(Journal!$N$5:$N$1504,Journal!$E$5:$E$1504,$A37)+IF($A37=2200,SUMIFS(Journal!$K$5:$K$1504,Journal!$J$5:$J$1504,"U"),0)) -> 0 | J37: =IF($A37="",0,IF($A37=3809,-MWST!$H$13,IF($A37=2200,MWST!$H$13,IF($A37=6800,Anlagen!$J$3,-SUMIF(Anlagen!$B$6:$B$105,$A37,Anlagen!$J$6:$J$105))))) -> 0 | K37: =IF($A37="","",IF(OR($C37="Aktiv",$C37="Aufwand"),$G37+$H37-$I37+$J37,$G37+$I37-$H37+$J37)) -> 12000
A38: 4210 | B38: Aufbereitung/Reparatur Handelsfahrzeuge (fremd) | C38: Aufwand | D38: MAT | E38: Fahrzeuge | G38: 0 | H38: =IF($A38="",0,SUMIFS(Journal!$M$5:$M$1504,Journal!$D$5:$D$1504,$A38)+IF($A38=1170,SUMIFS(Journal!$K$5:$K$1504,Journal!$J$5:$J$1504,"V",Journal!$G$5:$G$1504,"<>VI81"),0)+IF($A38=1171,SUMIFS(Journal!$K$5:$K$1504,Journal!$J$5:$J$1504,"V",Journal!$G$5:$G$1504,"VI81"),0)) -> 0 | I38: =IF($A38="",0,SUMIFS(Journal!$N$5:$N$1504,Journal!$E$5:$E$1504,$A38)+IF($A38=2200,SUMIFS(Journal!$K$5:$K$1504,Journal!$J$5:$J$1504,"U"),0)) -> 0 | J38: =IF($A38="",0,IF($A38=3809,-MWST!$H$13,IF($A38=2200,MWST!$H$13,IF($A38=6800,Anlagen!$J$3,-SUMIF(Anlagen!$B$6:$B$105,$A38,Anlagen!$J$6:$J$105))))) -> 0 | K38: =IF($A38="","",IF(OR($C38="Aktiv",$C38="Aufwand"),$G38+$H38-$I38+$J38,$G38+$I38-$H38+$J38)) -> 0
A39: 4400 | B39: Fremdarbeiten (Karosserie, Lack, Elektronik) | C39: Aufwand | D39: MAT | E39: Werkstatt | G39: 0 | H39: =IF($A39="",0,SUMIFS(Journal!$M$5:$M$1504,Journal!$D$5:$D$1504,$A39)+IF($A39=1170,SUMIFS(Journal!$K$5:$K$1504,Journal!$J$5:$J$1504,"V",Journal!$G$5:$G$1504,"<>VI81"),0)+IF($A39=1171,SUMIFS(Journal!$K$5:$K$1504,Journal!$J$5:$J$1504,"V",Journal!$G$5:$G$1504,"VI81"),0)) -> 0 | I39: =IF($A39="",0,SUMIFS(Journal!$N$5:$N$1504,Journal!$E$5:$E$1504,$A39)+IF($A39=2200,SUMIFS(Journal!$K$5:$K$1504,Journal!$J$5:$J$1504,"U"),0)) -> 0 | J39: =IF($A39="",0,IF($A39=3809,-MWST!$H$13,IF($A39=2200,MWST!$H$13,IF($A39=6800,Anlagen!$J$3,-SUMIF(Anlagen!$B$6:$B$105,$A39,Anlagen!$J$6:$J$105))))) -> 0 | K39: =IF($A39="","",IF(OR($C39="Aktiv",$C39="Aufwand"),$G39+$H39-$I39+$J39,$G39+$I39-$H39+$J39)) -> 0
A40: 4500 | B40: Betriebsmaterial (Öl, Verbrauch) | C40: Aufwand | D40: MAT | E40: Werkstatt | G40: 0 | H40: =IF($A40="",0,SUMIFS(Journal!$M$5:$M$1504,Journal!$D$5:$D$1504,$A40)+IF($A40=1170,SUMIFS(Journal!$K$5:$K$1504,Journal!$J$5:$J$1504,"V",Journal!$G$5:$G$1504,"<>VI81"),0)+IF($A40=1171,SUMIFS(Journal!$K$5:$K$1504,Journal!$J$5:$J$1504,"V",Journal!$G$5:$G$1504,"VI81"),0)) -> 0 | I40: =IF($A40="",0,SUMIFS(Journal!$N$5:$N$1504,Journal!$E$5:$E$1504,$A40)+IF($A40=2200,SUMIFS(Journal!$K$5:$K$1504,Journal!$J$5:$J$1504,"U"),0)) -> 0 | J40: =IF($A40="",0,IF($A40=3809,-MWST!$H$13,IF($A40=2200,MWST!$H$13,IF($A40=6800,Anlagen!$J$3,-SUMIF(Anlagen!$B$6:$B$105,$A40,Anlagen!$J$6:$J$105))))) -> 0 | K40: =IF($A40="","",IF(OR($C40="Aktiv",$C40="Aufwand"),$G40+$H40-$I40+$J40,$G40+$I40-$H40+$J40)) -> 0
A41: 4900 | B41: Lieferantenskonti & Rabatte | C41: Aufwand | D41: MAT | E41: Teile | G41: 0 | H41: =IF($A41="",0,SUMIFS(Journal!$M$5:$M$1504,Journal!$D$5:$D$1504,$A41)+IF($A41=1170,SUMIFS(Journal!$K$5:$K$1504,Journal!$J$5:$J$1504,"V",Journal!$G$5:$G$1504,"<>VI81"),0)+IF($A41=1171,SUMIFS(Journal!$K$5:$K$1504,Journal!$J$5:$J$1504,"V",Journal!$G$5:$G$1504,"VI81"),0)) -> 0 | I41: =IF($A41="",0,SUMIFS(Journal!$N$5:$N$1504,Journal!$E$5:$E$1504,$A41)+IF($A41=2200,SUMIFS(Journal!$K$5:$K$1504,Journal!$J$5:$J$1504,"U"),0)) -> 0 | J41: =IF($A41="",0,IF($A41=3809,-MWST!$H$13,IF($A41=2200,MWST!$H$13,IF($A41=6800,Anlagen!$J$3,-SUMIF(Anlagen!$B$6:$B$105,$A41,Anlagen!$J$6:$J$105))))) -> 0 | K41: =IF($A41="","",IF(OR($C41="Aktiv",$C41="Aufwand"),$G41+$H41-$I41+$J41,$G41+$I41-$H41+$J41)) -> 0
...

Sheet Journal
A1: Journal – alle Buchungen
A2: Pro Beleg eine Zeile: Soll-Konto an Haben-Konto, Betrag INKL. MWST, MWST-Code. Grau = automatisch.
A3: Beispiel: Kunde zahlt Rechnung bar → Soll 1000 (Kasse), Haben 3000 (Werkstatt). Einkauf Teile auf Rechnung → Soll 4000, Haben 2000. Die Zeilen 'BEISPIEL' löschen, sobald du eigene Daten erfasst.
A4: Datum | B4: Beleg-Nr. | C4: Buchungstext | D4: Soll-Konto | E4: Haben-Konto | F4: Betrag inkl. MWST | G4: MWST-Code | H4: MWST-Satz | I4: Art | J4: Art (aktiv) | K4: MWST-Betrag | L4: Netto | M4: Soll-Buchung | N4: Haben-Buchung | O4: Monat | P4: Quartal | Q4: Semester | R4: Saldo-Grp Haben | S4: Saldo-Grp Soll | T4: Typ Soll | U4: Typ Haben | V4: Prüfung | W4: Auszug-Nr
A5: 46031 | B5: R-001 | C5: BEISPIEL Service + Bremsen VW Polo, Arbeit | D5: 1100 | E5: 3000 | F5: 1621.5 | G5: U81 | H5: =IF($G5="",0,IFERROR(INDEX(Einstellungen!$G$5:$G$11,MATCH($G5,Einstellungen!$E$5:$E$11,0)),0)) -> 0.081 | I5: =IF($G5="","-",IFERROR(INDEX(Einstellungen!$H$5:$H$11,MATCH($G5,Einstellungen!$E$5:$E$11,0)),"-")) -> U | J5: =IF(AND(Einstellungen!$B$8="Ja",Einstellungen!$B$9="Effektiv"),$I5,"-") -> - | K5: =IF(OR($F5="",$J5="-"),0,ROUND($F5-$F5/(1+$H5),2)) -> 0 | L5: =IF($F5="",0,$F5-$K5) -> 1621.5 | M5: =IF($F5="",0,IF($J5="V",$L5,$F5)) -> 1621.5 | N5: =IF($F5="",0,IF($J5="U",$L5,$F5)) -> 1621.5 | O5: =IF($A5="","",MONTH($A5)) -> 1 | P5: =IF($A5="","",ROUNDUP(MONTH($A5)/3,0)) -> 1 | Q5: =IF($A5="","",IF(MONTH($A5)<=6,1,2)) -> 1 | R5: =IF($E5="","",IFERROR(INDEX(Kontenplan!$F$5:$F$90,MATCH($E5,Kontenplan!$A$5:$A$90,0)),"")) -> 1 | S5: =IF($D5="","",IFERROR(INDEX(Kontenplan!$F$5:$F$90,MATCH($D5,Kontenplan!$A$5:$A$90,0)),"")) -> 0 | T5: =IF($D5="","",IFERROR(INDEX(Kontenplan!$C$5:$C$90,MATCH($D5,Kontenplan!$A$5:$A$90,0)),"?")) -> Aktiv | U5: =IF($E5="","",IFERROR(INDEX(Kontenplan!$C$5:$C$90,MATCH($E5,Kontenplan!$A$5:$A$90,0)),"?")) -> Ertrag | V5: =IF($F5="","",IF(OR($D5="",$E5="",$T5="?",$U5="?"),"Konto prüfen!",IF($A5="","Datum fehlt",IF(YEAR($A5)<>Einstellungen!$B$7,"anderes Jahr!",IF($G5="","MWST-Code fehlt","OK"))))) -> OK | W5: =IF($F5="","",IF(OR($D5=Kontoauszug!$C$4,$E5=Kontoauszug!$C$4),MAX(W$4:W4)+1,""))
A6: 46031 | B6: R-001 | C6: BEISPIEL Service VW Polo, Ersatzteile | D6: 1100 | E6: 3200 | F6: 864.8 | G6: U81 | H6: =IF($G6="",0,IFERROR(INDEX(Einstellungen!$G$5:$G$11,MATCH($G6,Einstellungen!$E$5:$E$11,0)),0)) -> 0.081 | I6: =IF($G6="","-",IFERROR(INDEX(Einstellungen!$H$5:$H$11,MATCH($G6,Einstellungen!$E$5:$E$11,0)),"-")) -> U | J6: =IF(AND(Einstellungen!$B$8="Ja",Einstellungen!$B$9="Effektiv"),$I6,"-") -> - | K6: =IF(OR($F6="",$J6="-"),0,ROUND($F6-$F6/(1+$H6),2)) -> 0 | L6: =IF($F6="",0,$F6-$K6) -> 864.8 | M6: =IF($F6="",0,IF($J6="V",$L6,$F6)) -> 864.8 | N6: =IF($F6="",0,IF($J6="U",$L6,$F6)) -> 864.8 | O6: =IF($A6="","",MONTH($A6)) -> 1 | P6: =IF($A6="","",ROUNDUP(MONTH($A6)/3,0)) -> 1 | Q6: =IF($A6="","",IF(MONTH($A6)<=6,1,2)) -> 1 | R6: =IF($E6="","",IFERROR(INDEX(Kontenplan!$F$5:$F$90,MATCH($E6,Kontenplan!$A$5:$A$90,0)),"")) -> 1 | S6: =IF($D6="","",IFERROR(INDEX(Kontenplan!$F$5:$F$90,MATCH($D6,Kontenplan!$A$5:$A$90,0)),"")) -> 0 | T6: =IF($D6="","",IFERROR(INDEX(Kontenplan!$C$5:$C$90,MATCH($D6,Kontenplan!$A$5:$A$90,0)),"?")) -> Aktiv | U6: =IF($E6="","",IFERROR(INDEX(Kontenplan!$C$5:$C$90,MATCH($E6,Kontenplan!$A$5:$A$90,0)),"?")) -> Ertrag | V6: =IF($F6="","",IF(OR($D6="",$E6="",$T6="?",$U6="?"),"Konto prüfen!",IF($A6="","Datum fehlt",IF(YEAR($A6)<>Einstellungen!$B$7,"anderes Jahr!",IF($G6="","MWST-Code fehlt","OK"))))) -> OK | W6: =IF($F6="","",IF(OR($D6=Kontoauszug!$C$4,$E6=Kontoauszug!$C$4),MAX(W$4:W5)+1,""))
A7: 46034 | B7: K-001 | C7: BEISPIEL Einkauf Ersatzteile Grosshändler | D7: 4000 | E7: 2000 | F7: 1297.2 | G7: V81 | H7: =IF($G7="",0,IFERROR(INDEX(Einstellungen!$G$5:$G$11,MATCH($G7,Einstellungen!$E$5:$E$11,0)),0)) -> 0.081 | I7: =IF($G7="","-",IFERROR(INDEX(Einstellungen!$H$5:$H$11,MATCH($G7,Einstellungen!$E$5:$E$11,0)),"-")) -> V | J7: =IF(AND(Einstellungen!$B$8="Ja",Einstellungen!$B$9="Effektiv"),$I7,"-") -> - | K7: =IF(OR($F7="",$J7="-"),0,ROUND($F7-$F7/(1+$H7),2)) -> 0 | L7: =IF($F7="",0,$F7-$K7) -> 1297.2 | M7: =IF($F7="",0,IF($J7="V",$L7,$F7)) -> 1297.2 | N7: =IF($F7="",0,IF($J7="U",$L7,$F7)) -> 1297.2 | O7: =IF($A7="","",MONTH($A7)) -> 1 | P7: =IF($A7="","",ROUNDUP(MONTH($A7)/3,0)) -> 1 | Q7: =IF($A7="","",IF(MONTH($A7)<=6,1,2)) -> 1 | R7: =IF($E7="","",IFERROR(INDEX(Kontenplan!$F$5:$F$90,MATCH($E7,Kontenplan!$A$5:$A$90,0)),"")) -> 0 | S7: =IF($D7="","",IFERROR(INDEX(Kontenplan!$F$5:$F$90,MATCH($D7,Kontenplan!$A$5:$A$90,0)),"")) -> 0 | T7: =IF($D7="","",IFERROR(INDEX(Kontenplan!$C$5:$C$90,MATCH($D7,Kontenplan!$A$5:$A$90,0)),"?")) -> Aufwand | U7: =IF($E7="","",IFERROR(INDEX(Kontenplan!$C$5:$C$90,MATCH($E7,Kontenplan!$A$5:$A$90,0)),"?")) -> Passiv | V7: =IF($F7="","",IF(OR($D7="",$E7="",$T7="?",$U7="?"),"Konto prüfen!",IF($A7="","Datum fehlt",IF(YEAR($A7)<>Einstellungen!$B$7,"anderes Jahr!",IF($G7="","MWST-Code fehlt","OK"))))) -> OK | W7: =IF($F7="","",IF(OR($D7=Kontoauszug!$C$4,$E7=Kontoauszug!$C$4),MAX(W$4:W6)+1,""))
A8: 46037 | B8: Q-001 | C8: BEISPIEL Barverkauf Pneuwechsel | D8: 1000 | E8: 3210 | F8: 120 | G8: U81 | H8: =IF($G8="",0,IFERROR(INDEX(Einstellungen!$G$5:$G$11,MATCH($G8,Einstellungen!$E$5:$E$11,0)),0)) -> 0.081 | I8: =IF($G8="","-",IFERROR(INDEX(Einstellungen!$H$5:$H$11,MATCH($G8,Einstellungen!$E$5:$E$11,0)),"-")) -> U | J8: =IF(AND(Einstellungen!$B$8="Ja",Einstellungen!$B$9="Effektiv"),$I8,"-") -> - | K8: =IF(OR($F8="",$J8="-"),0,ROUND($F8-$F8/(1+$H8),2)) -> 0 | L8: =IF($F8="",0,$F8-$K8) -> 120 | M8: =IF($F8="",0,IF($J8="V",$L8,$F8)) -> 120 | N8: =IF($F8="",0,IF($J8="U",$L8,$F8)) -> 120 | O8: =IF($A8="","",MONTH($A8)) -> 1 | P8: =IF($A8="","",ROUNDUP(MONTH($A8)/3,0)) -> 1 | Q8: =IF($A8="","",IF(MONTH($A8)<=6,1,2)) -> 1 | R8: =IF($E8="","",IFERROR(INDEX(Kontenplan!$F$5:$F$90,MATCH($E8,Kontenplan!$A$5:$A$90,0)),"")) -> 1 | S8: =IF($D8="","",IFERROR(INDEX(Kontenplan!$F$5:$F$90,MATCH($D8,Kontenplan!$A$5:$A$90,0)),"")) -> 0 | T8: =IF($D8="","",IFERROR(INDEX(Kontenplan!$C$5:$C$90,MATCH($D8,Kontenplan!$A$5:$A$90,0)),"?")) -> Aktiv | U8: =IF($E8="","",IFERROR(INDEX(Kontenplan!$C$5:$C$90,MATCH($E8,Kontenplan!$A$5:$A$90,0)),"?")) -> Ertrag | V8: =IF($F8="","",IF(OR($D8="",$E8="",$T8="?",$U8="?"),"Konto prüfen!",IF($A8="","Datum fehlt",IF(YEAR($A8)<>Einstellungen!$B$7,"anderes Jahr!",IF($G8="","MWST-Code fehlt","OK"))))) -> OK | W8: =IF($F8="","",IF(OR($D8=Kontoauszug!$C$4,$E8=Kontoauszug!$C$4),MAX(W$4:W7)+1,""))
A9: 46047 | B9: L-001 | C9: BEISPIEL Lohn Mechaniker Januar (netto) | D9: 5000 | E9: 1020 | F9: 4650 | G9: - | H9: =IF($G9="",0,IFERROR(INDEX(Einstellungen!$G$5:$G$11,MATCH($G9,Einstellungen!$E$5:$E$11,0)),0)) -> 0 | I9: =IF($G9="","-",IFERROR(INDEX(Einstellungen!$H$5:$H$11,MATCH($G9,Einstellungen!$E$5:$E$11,0)),"-")) -> - | J9: =IF(AND(Einstellungen!$B$8="Ja",Einstellungen!$B$9="Effektiv"),$I9,"-") -> - | K9: =IF(OR($F9="",$J9="-"),0,ROUND($F9-$F9/(1+$H9),2)) -> 0 | L9: =IF($F9="",0,$F9-$K9) -> 4650 | M9: =IF($F9="",0,IF($J9="V",$L9,$F9)) -> 4650 | N9: =IF($F9="",0,IF($J9="U",$L9,$F9)) -> 4650 | O9: =IF($A9="","",MONTH($A9)) -> 1 | P9: =IF($A9="","",ROUNDUP(MONTH($A9)/3,0)) -> 1 | Q9: =IF($A9="","",IF(MONTH($A9)<=6,1,2)) -> 1 | R9: =IF($E9="","",IFERROR(INDEX(Kontenplan!$F$5:$F$90,MATCH($E9,Kontenplan!$A$5:$A$90,0)),"")) -> 0 | S9: =IF($D9="","",IFERROR(INDEX(Kontenplan!$F$5:$F$90,MATCH($D9,Kontenplan!$A$5:$A$90,0)),"")) -> 0 | T9: =IF($D9="","",IFERROR(INDEX(Kontenplan!$C$5:$C$90,MATCH($D9,Kontenplan!$A$5:$A$90,0)),"?")) -> Aufwand | U9: =IF($E9="","",IFERROR(INDEX(Kontenplan!$C$5:$C$90,MATCH($E9,Kontenplan!$A$5:$A$90,0)),"?")) -> Aktiv | V9: =IF($F9="","",IF(OR($D9="",$E9="",$T9="?",$U9="?"),"Konto prüfen!",IF($A9="","Datum fehlt",IF(YEAR($A9)<>Einstellungen!$B$7,"anderes Jahr!",IF($G9="","MWST-Code fehlt","OK"))))) -> OK | W9: =IF($F9="","",IF(OR($D9=Kontoauszug!$C$4,$E9=Kontoauszug!$C$4),MAX(W$4:W8)+1,"")) -> 1
A10: 46047 | B10: L-001 | C10: BEISPIEL AN-Abzüge Mechaniker Januar | D10: 5000 | E10: 2270 | F10: 550 | G10: - | H10: =IF($G10="",0,IFERROR(INDEX(Einstellungen!$G$5:$G$11,MATCH($G10,Einstellungen!$E$5:$E$11,0)),0)) -> 0 | I10: =IF($G10="","-",IFERROR(INDEX(Einstellungen!$H$5:$H$11,MATCH($G10,Einstellungen!$E$5:$E$11,0)),"-")) -> - | J10: =IF(AND(Einstellungen!$B$8="Ja",Einstellungen!$B$9="Effektiv"),$I10,"-") -> - | K10: =IF(OR($F10="",$J10="-"),0,ROUND($F10-$F10/(1+$H10),2)) -> 0 | L10: =IF($F10="",0,$F10-$K10) -> 550 | M10: =IF($F10="",0,IF($J10="V",$L10,$F10)) -> 550 | N10: =IF($F10="",0,IF($J10="U",$L10,$F10)) -> 550 | O10: =IF($A10="","",MONTH($A10)) -> 1 | P10: =IF($A10="","",ROUNDUP(MONTH($A10)/3,0)) -> 1 | Q10: =IF($A10="","",IF(MONTH($A10)<=6,1,2)) -> 1 | R10: =IF($E10="","",IFERROR(INDEX(Kontenplan!$F$5:$F$90,MATCH($E10,Kontenplan!$A$5:$A$90,0)),"")) -> 0 | S10: =IF($D10="","",IFERROR(INDEX(Kontenplan!$F$5:$F$90,MATCH($D10,Kontenplan!$A$5:$A$90,0)),"")) -> 0 | T10: =IF($D10="","",IFERROR(INDEX(Kontenplan!$C$5:$C$90,MATCH($D10,Kontenplan!$A$5:$A$90,0)),"?")) -> Aufwand | U10: =IF($E10="","",IFERROR(INDEX(Kontenplan!$C$5:$C$90,MATCH($E10,Kontenplan!$A$5:$A$90,0)),"?")) -> Passiv | V10: =IF($F10="","",IF(OR($D10="",$E10="",$T10="?",$U10="?"),"Konto prüfen!",IF($A10="","Datum fehlt",IF(YEAR($A10)<>Einstellungen!$B$7,"anderes Jahr!",IF($G10="","MWST-Code fehlt","OK"))))) -> OK | W10: =IF($F10="","",IF(OR($D10=Kontoauszug!$C$4,$E10=Kontoauszug!$C$4),MAX(W$4:W9)+1,""))
